Workbook

Sheet Assunzioni
A1: AInima — Assunzioni del Piano Finanziario
A2: Tutte le celle blu sono ipotesi modificabili. Le formule nelle altre schede si aggiornano automaticamente.
A4: Parametri generali
A5: Capitale iniziale disponibile (€) | B5: 5000 | C5: Investimento personale dichiarato
A6: Prezzo per utente per match confermato (€) | B6: 20 | C6: AGGIORNATO a 20€ (era 15€): a 15€ il netto reale del primo anno in regime forfettario risultava negativo (-598€) una volta inclusi imposta sostitutiva, INPS su base presunta e commercialista. A 20€ il margine reale (36%) si allontana a sufficienza dal coefficiente presunto forfettario (78%) da restare positivo (+1.867€ netto anno 1). Contropartita: il passaggio a SRL diventa necessario prima (vedi assunzione dedicata), perché il fatturato anno 2 supera più rapidamente la soglia forfettario di 85.000€.
A7: Riserva di cassa minima da mantenere (€) | B7: 300 | C7: Buffer di sicurezza: sotto questa soglia si sospende la pubblicità
A8: Commissioni di incasso pagamenti (% sui ricavi) | B8: 0.04 | C8: Stima Stripe: 1.5% + 0.25€/transazione su ticket da 10€
A10: Crescita utenti — Milano
A11: Iscritti organici al mese 0 (promozione volontaria) | B11: 10 | C11: RIVISTO: 2 canali. (1) Metro+quartieri mirati: ~1.300 volantini/mese, conversione 0,4% (pubblico freddo) = ~5/mese. (2) Feste sudamericane: assunzione 2 eventi/mese x ~40 volantini mirati/evento, conversione 6% (contesto sociale/conversazionale) = ~5/mese. Totale ~10/mese. Da affinare con la frequenza reale degli eventi.
A12: Crescita mensile iscritti organici Milano (%) | B12: 0.03 | C12: Effetto passaparola/referral crescente
A13: CAC pubblicitario Milano (€/iscritto) | B13: 8 | C13: Google Ads su keyword ad alta intenzione — DA VALIDARE con test reale
A14: Budget mensile servizio di distribuzione mirata (€) | B14: 100 | C14: Servizio di volantinaggio a pagamento MIRATO su luoghi ad alta conversione (palestre, coworking, zone business) — non la metro fredda. ~90-120€/sessione, 1.500-2.000 volantini, conversione 2-3% (contesto scelto, non casuale).
A15: CAC servizio di distribuzione mirata (€/iscritto) | B15: 4 | C15: Stima: 100€/sessione, ~1.700 volantini, conversione ~2,5% su luoghi mirati = 100/(1700x0,025) = ~2,3€; teniamo 4€ come margine prudenziale, comunque molto meglio di Google Ads (8€).
A16: Mese di lancio di questo canale | B16: 1 | C16: Parte da M1, un mese dopo l'avvio, per dare tempo di scegliere i luoghi migliori
A17: Mese di lancio del matching a Milano | B17: 3 | C17: Dopo aver raggiunto una massa critica di iscritti bilanciata M/F
A19: Crescita utenti — Dubai
A20: Mese di lancio Dubai | B20: 4 | C20: Danae inizia la promozione locale
A21: Iscritti organici al mese di lancio (promozione volontaria) | B21: 10 | C21: Volantinaggio/eventi locali gestiti da Danae
A22: Crescita mensile iscritti organici Dubai (%) | B22: 0.04 | C22: Mercato più recettivo al matchmaking strutturato
A23: CAC pubblicitario Dubai (€/iscritto) | B23: 10 | C23: Stima prudenziale — DA VALIDARE con test reale
A24: Mese di lancio del matching a Dubai | B24: 7 | C24: Dopo massa critica locale
A26: Conversione in ricavi
A27: Quota iscritti 'attivi' nel matching (%) | B27: 0.8 | C27: Il resto è in attesa/incompleto/inattivo
A28: Tasso di conferma match iniziale (%/mese) | B28: 0.05 | C28: Quota di utenti attivi che ogni mese confermano un match pagante — cold start
A29: Tasso di conferma match a regime (%/mese) | B29: 0.15 | C29: Una volta che il database è maturo e bilanciato
A30: Mesi di ramp-up per raggiungere il tasso a regime | B30: 9 | C30: Ramp lineare
A31: Tasso di abbandono mensile del pool di ricerca (%) | B31: 0.02 | C31: AGGIORNATO (ottimistico): dato che anche chi ha una relazione stabile può richiedere nuovi abbinamenti (rubrica), l'abbandono reale è solo chi si stufa della piattaforma o cambia vita — quota più piccola del 4% iniziale.
A32: Soglia utenti attivi per aumentare la frequenza di abbinamento | B32: 500 | C32: Il vincolo di 1 proposta/mese è elastico, non tecnico: serve a far crescere il DB senza esaurirlo. Superata questa soglia di utenti attivi (~M11-M12 nello scenario base) si può aumentare la frequenza.
A33: Moltiplicatore frequenza abbinamenti dopo la soglia | B33: 2 | C33: Es. 2 = da 1 a 2 proposte/mese per utente in ricerca, raddoppiando il potenziale di ricavo per utente attivo. Modificabile: prova anche 1,5 o 3 per vedere l'impatto.
A34: Sconto di conferma sulle proposte aggiuntive oltre la prima (%) | B34: 0.35 | C34: La 2a+ proposta nello stesso mese è il candidato successivo nel ranking, quindi mediamente meno compatibile: confermata con probabilità ridotta rispetto alla 1a. 35% = la 2a proposta converte al 65% del tasso della prima.
A36: Costi IT
A37: Claude Code (€/mese) | B37: 25 | C37: Come indicato da te
A38: Hosting Web MVP (€/mese) | B38: 20 | C38: VPS piccolo (es. Hetzner/DigitalOcean) — stima
A39: Hosting dopo lancio App Mobile (€/mese) | B39: 35 | C39: Backend più robusto per servire anche le app
A40: Mese di avvio sviluppo App Mobile | B40: 9 | C40: Dopo validazione del modello sul web
A41: Costo unitario stimato API LLM per utente attivo (€/utente/mese) | B41: 0.05 | C41: Claude Haiku 4.5, $1/$5 per MTok — profilazione + report + analisi mensile
A42: Costo dominio .com (una tantum, €) | B42: 15 | C42: Registrazione annuale tipica
A43: Apple Developer Program (una tantum, €/anno) | B43: 95 | C43: Necessario per pubblicare su App Store
A44: Google Play Console (una tantum, €) | B44: 23 | C44: Costo di attivazione singolo
A45: Soglia iscritti per passare a piano mailing a pagamento | B45: 2000 | C45: Brevo free fino a 9.000 email/mese: con newsletter settimanale regge fino a ~2.000 iscritti
...

Sheet Piano Mensile
A1: AInima — Piano Mensile (24 mesi)
A2: Indice mese (numero) | C2: 0 | D2: 1 | E2: 2 | F2: 3 | G2: 4 | H2: 5 | I2: 6 | J2: 7 | K2: 8 | L2: 9 | M2: 10 | N2: 11 | O2: 12 | P2: 13 | Q2: 14 | R2: 15 | S2: 16 | T2: 17 | U2: 18 | V2: 19 | W2: 20 | X2: 21 | Y2: 22 | Z2: 23
A3: Mese | C3: ="M"&C2 -> M0 | D3: ="M"&D2 -> M1 | E3: ="M"&E2 -> M2 | F3: ="M"&F2 -> M3 | G3: ="M"&G2 -> M4 | H3: ="M"&H2 -> M5 | I3: ="M"&I2 -> M6 | J3: ="M"&J2 -> M7 | ... Z3: ="M"&Z2 -> M23
A5: CRESCITA UTENTI
A6: Nuovi iscritti Milano — organici (tuo tempo personale) | C6: =Assunzioni!$B$11 -> 10 | D6: =ROUND(C6*(1+Assunzioni!$B$12),0) -> 10 | E6: =ROUND(D6*(1+Assunzioni!$B$12),0) -> 10 | F6: =ROUND(E6*(1+Assunzioni!$B$12),0) -> 10 | G6: =ROUND(F6*(1+Assunzioni!$B$12),0) -> 10 | H6: =ROUND(G6*(1+Assunzioni!$B$12),0) -> 10 | I6: =ROUND(H6*(1+Assunzioni!$B$12),0) -> 10 | J6: =ROUND(I6*(1+Assunzioni!$B$12),0) -> 10 | K6: =ROUND(J6*(1+Assunzioni!$B$12),0) -> 10 | ... Z6: =ROUND(Y6*(1+Assunzioni!$B$12),0) -> 10
A7: Nuovi iscritti Milano — servizio distribuzione mirata (a pagamento) | C7: =IF(C$2>=Assunzioni!$B$16,Assunzioni!$B$14/Assunzioni!$B$15,0) -> 0 | D7: =IF(D$2>=Assunzioni!$B$16,Assunzioni!$B$14/Assunzioni!$B$15,0) -> 25 | E7: =IF(E$2>=Assunzioni!$B$16,Assunzioni!$B$14/Assunzioni!$B$15,0) -> 25 | F7: =IF(F$2>=Assunzioni!$B$16,Assunzioni!$B$14/Assunzioni!$B$15,0) -> 25 | G7: =IF(G$2>=Assunzioni!$B$16,Assunzioni!$B$14/Assunzioni!$B$15,0) -> 25 | H7: =IF(H$2>=Assunzioni!$B$16,Assunzioni!$B$14/Assunzioni!$B$15,0) -> 25 | I7: =IF(I$2>=Assunzioni!$B$16,Assunzioni!$B$14/Assunzioni!$B$15,0) -> 25 | J7: =IF(J$2>=Assunzioni!$B$16,Assunzioni!$B$14/Assunzioni!$B$15,0) -> 25 | ... Z7: =IF(Z$2>=Assunzioni!$B$16,Assunzioni!$B$14/Assunzioni!$B$15,0) -> 25
A8: Nuovi iscritti Milano — da Google Ads | C8: =IFERROR(C46/Assunzioni!$B$13,0) -> 25 | D8: =IFERROR(D46/Assunzioni!$B$13,0) -> 25 | E8: =IFERROR(E46/Assunzioni!$B$13,0) -> 25 | F8: =IFERROR(F46/Assunzioni!$B$13,0) -> 25 | G8: =IFERROR(G46/Assunzioni!$B$13,0) -> 21.45 | H8: =IFERROR(H46/Assunzioni!$B$13,0) -> 24.0831 | I8: =IFERROR(I46/Assunzioni!$B$13,0) -> 27.193824 | J8: =IFERROR(J46/Assunzioni!$B$13,0) -> 30.819977 | ... Z8: =IFERROR(Z46/Assunzioni!$B$13,0) -> 464.92764
A9: Nuovi iscritti Dubai — organici | C9: =IF(C$2=Assunzioni!$B$20,Assunzioni!$B$21,0) -> 0 | D9: =IF(D$2=Assunzioni!$B$20,Assunzioni!$B$21,IF(D$2>Assunzioni!$B$20,ROUND(C9*(1+Assunzioni!$B$22),0),0)) -> 0 | E9: =IF(E$2=Assunzioni!$B$20,Assunzioni!$B$21,IF(E$2>Assunzioni!$B$20,ROUND(D9*(1+Assunzioni!$B$22),0),0)) -> 0 | F9: =IF(F$2=Assunzioni!$B$20,Assunzioni!$B$21,IF(F$2>Assunzioni!$B$20,ROUND(E9*(1+Assunzioni!$B$22),0),0)) -> 0 | G9: =IF(G$2=Assunzioni!$B$20,Assunzioni!$B$21,IF(G$2>Assunzioni!$B$20,ROUND(F9*(1+Assunzioni!$B$22),0),0)) -> 10 | H9: =IF(H$2=Assunzioni!$B$20,Assunzioni!$B$21,IF(H$2>Assunzioni!$B$20,ROUND(G9*(1+Assunzioni!$B$22),0),0)) -> 10 | I9: =IF(I$2=Assunzioni!$B$20,Assunzioni!$B$21,IF(I$2>Assunzioni!$B$20,ROUND(H9*(1+Assunzioni!$B$22),0),0)) -> 10 | J9: =IF(J$2=Assunzioni!$B$20,Assunzioni!$B$21,IF(J$2>Assunzioni!$B$20,ROUND(I9*(1+Assunzioni!$B$22),0),0)) -> 10 | K9: =IF(K$2=Assunzioni!$B$20,Assunzioni!$B$21,IF(K$2>Assunzioni!$B$20,ROUND(J9*(1+Assunzioni!$B$22),0),0)) -> 10 | ... Z9: =IF(Z$2=Assunzioni!$B$20,Assunzioni!$B$21,IF(Z$2>Assunzioni!$B$20,ROUND(Y9*(1+Assunzioni!$B$22),0),0)) -> 10
A10: Nuovi iscritti Dubai — da advertising | C10: =IFERROR(C47/Assunzioni!$B$23,0) -> 0 | D10: =IFERROR(D47/Assunzioni!$B$23,0) -> 0 | E10: =IFERROR(E47/Assunzioni!$B$23,0) -> 0 | F10: =IFERROR(F47/Assunzioni!$B$23,0) -> 0 | G10: =IFERROR(G47/Assunzioni!$B$23,0) -> 11.44 | H10: =IFERROR(H47/Assunzioni!$B$23,0) -> 12.84432 | I10: =IFERROR(I47/Assunzioni!$B$23,0) -> 14.503373 | J10: =IFERROR(J47/Assunzioni!$B$23,0) -> 16.437321 | ... Z10: =IFERROR(Z47/Assunzioni!$B$23,0) -> 247.96141
A11: Totale nuovi iscritti | C11: =SUM(C6:C10) -> 35 | D11: =SUM(D6:D10) -> 60 | E11: =SUM(E6:E10) -> 60 | F11: =SUM(F6:F10) -> 60 | G11: =SUM(G6:G10) -> 77.89 | H11: =SUM(H6:H10) -> 81.92742 | I11: =SUM(I6:I10) -> 86.697196 | J11: =SUM(J6:J10) -> 92.257298 | ... Z11: =SUM(Z6:Z10) -> 757.88904
A12: Iscritti cumulati Milano | C12: =C6+C7+C8 -> 35 | D12: =C12+D6+D7+D8 -> 95 | E12: =D12+E6+E7+E8 -> 155 | F12: =E12+F6+F7+F8 -> 215 | G12: =F12+G6+G7+G8 -> 271.45 | H12: =G12+H6+H7+H8 -> 330.5331 | I12: =H12+I6+I7+I8 -> 392.72692 | J12: =I12+J6+J7+J8 -> 458.5469 | K12: =J12+K6+K7+K8 -> 532.93508 | ... Z12: =Y12+Z6+Z7+Z8 -> 4386.7999
A13: Iscritti cumulati Dubai | C13: =C9+C10 -> 0 | D13: =C13+D9+D10 -> 0 | E13: =D13+E9+E10 -> 0 | F13: =E13+F9+F10 -> 0 | G13: =F13+G9+G10 -> 21.44 | H13: =G13+H9+H10 -> 44.28432 | I13: =H13+I9+I10 -> 68.787693 | J13: =I13+J9+J10 -> 95.225014 | K13: =J13+K9+K10 -> 126.23204 | ... Z13: =Y13+Z9+Z10 -> 2051.6266
A14: Iscritti cumulati Totale | C14: =C12+C13 -> 35 | D14: =D12+D13 -> 95 | E14: =E12+E13 -> 155 | F14: =F12+F13 -> 215 | G14: =G12+G13 -> 292.89 | H14: =H12+H13 -> 374.81742 | I14: =I12+I13 -> 461.51462 | J14: =J12+J13 -> 553.77191 | ... Z14: =Z12+Z13 -> 6438.4265
A15: Utenti attivi nel matching — Milano | C15: =IF(C$2>=Assunzioni!$B$17,C12*Assunzioni!$B$27,0) -> 0 | D15: =IF(D$2>=Assunzioni!$B$17,D12*Assunzioni!$B$27,0) -> 0 | E15: =IF(E$2>=Assunzioni!$B$17,E12*Assunzioni!$B$27,0) -> 0 | F15: =IF(F$2>=Assunzioni!$B$17,F12*Assunzioni!$B$27,0) -> 172 | G15: =IF(G$2>=Assunzioni!$B$17,G12*Assunzioni!$B$27,0) -> 217.16 | H15: =IF(H$2>=Assunzioni!$B$17,H12*Assunzioni!$B$27,0) -> 264.42648 | I15: =IF(I$2>=Assunzioni!$B$17,I12*Assunzioni!$B$27,0) -> 314.18154 | J15: =IF(J$2>=Assunzioni!$B$17,J12*Assunzioni!$B$27,0) -> 366.83752 | ... Z15: =IF(Z$2>=Assunzioni!$B$17,Z12*Assunzioni!$B$27,0) -> 3509.4399
A16: Utenti attivi nel matching — Dubai | C16: =IF(C$2>=Assunzioni!$B$24,C13*Assunzioni!$B$27,0) -> 0 | D16: =IF(D$2>=Assunzioni!$B$24,D13*Assunzioni!$B$27,0) -> 0 | E16: =IF(E$2>=Assunzioni!$B$24,E13*Assunzioni!$B$27,0) -> 0 | F16: =IF(F$2>=Assunzioni!$B$24,F13*Assunzioni!$B$27,0) -> 0 | G16: =IF(G$2>=Assunzioni!$B$24,G13*Assunzioni!$B$27,0) -> 0 | H16: =IF(H$2>=Assunzioni!$B$24,H13*Assunzioni!$B$27,0) -> 0 | I16: =IF(I$2>=Assunzioni!$B$24,I13*Assunzioni!$B$27,0) -> 0 | J16: =IF(J$2>=Assunzioni!$B$24,J13*Assunzioni!$B$27,0) -> 76.180011 | ... Z16: =IF(Z$2>=Assunzioni!$B$24,Z13*Assunzioni!$B$27,0) -> 1641.3013
A17: Utenti attivi nel matching — Totale | C17: =C15+C16 -> 0 | D17: =D15+D16 -> 0 | E17: =E15+E16 -> 0 | F17: =F15+F16 -> 172 | G17: =G15+G16 -> 217.16 | H17: =H15+H16 -> 264.42648 | I17: =I15+I16 -> 314.18154 | J17: =J15+J16 -> 443.01753 | ... Z17: =Z15+Z16 -> 5150.7412
A18: — di cui usciti dalla ricerca (abbandono cumulato, non per match) | C18: =0+C19*Assunzioni!$B$31 -> 0 | D18: =C18+D19*Assunzioni!$B$31 -> 0 | E18: =D18+E19*Assunzioni!$B$31 -> 0 | F18: =E18+F19*Assunzioni!$B$31 -> 3.44 | G18: =F18+G19*Assunzioni!$B$31 -> 7.7144 | H18: =G18+H19*Assunzioni!$B$31 -> 12.848642 | I18: =H18+I19*Assunzioni!$B$31 -> 18.8753 | J18: =I18+J19*Assunzioni!$B$31 -> 27.358144 | K18: =J18+K19*Assunzioni!$B$31 -> 37.357655 | ... Z18: =Y18+Z19*Assunzioni!$B$31 -> 676.77617
A19: Utenti ancora in ricerca attiva (pool disponibile) | C19: =MAX(0,C17-0) -> 0 | D19: =MAX(0,D17-C18) -> 0 | E19: =MAX(0,E17-D18) -> 0 | F19: =MAX(0,F17-E18) -> 172 | G19: =MAX(0,G17-F18) -> 213.72 | H19: =MAX(0,H17-G18) -> 256.71208 | I19: =MAX(0,I17-H18) -> 301.3329 | J19: =MAX(0,J17-I18) -> 424.14223 | K19: =MAX(0,K17-J18) -> 499.97555 | ... Z19: =MAX(0,Z17-Y18) -> 4565.2704
A21: RICAVI
A22: Tasso di conferma match (%/mese, su chi è in ricerca) | C22: =Assunzioni!$B$28+(Assunzioni!$B$29-Assunzioni!$B$28)*MIN(1,C$2/Assunzioni!$B$30) -> 0.05 | D22: =Assunzioni!$B$28+(Assunzioni!$B$29-Assunzioni!$B$28)*MIN(1,D$2/Assunzioni!$B$30) -> 0.061111111 | E22: =Assunzioni!$B$28+(Assunzioni!$B$29-Assunzioni!$B$28)*MIN(1,E$2/Assunzioni!$B$30) -> 0.072222222 | F22: =Assunzioni!$B$28+(Assunzioni!$B$29-Assunzioni!$B$28)*MIN(1,F$2/Assunzioni!$B$30) -> 0.083333333 | G22: =Assunzioni!$B$28+(Assunzioni!$B$29-Assunzioni!$B$28)*MIN(1,G$2/Assunzioni!$B$30) -> 0.094444444 | H22: =Assunzioni!$B$28+(Assunzioni!$B$29-Assunzioni!$B$28)*MIN(1,H$2/Assunzioni!$B$30) -> 0.10555556 | I22: =Assunzioni!$B$28+(Assunzioni!$B$29-Assunzioni!$B$28)*MIN(1,I$2/Assunzioni!$B$30) -> 0.11666667 | J22: =Assunzioni!$B$28+(Assunzioni!$B$29-Assunzioni!$B$28)*MIN(1,J$2/Assunzioni!$B$30) -> 0.12777778 | ... Z22: =Assunzioni!$B$28+(Assunzioni!$B$29-Assunzioni!$B$28)*MIN(1,Z$2/Assunzioni!$B$30) -> 0.15
A23: Moltiplicatore frequenza (1x finché il DB è piccolo, poi aumenta) | C23: =IF(C17>=Assunzioni!$B$32,Assunzioni!$B$33,1) -> 1 | D23: =IF(D17>=Assunzioni!$B$32,Assunzioni!$B$33,1) -> 1 | E23: =IF(E17>=Assunzioni!$B$32,Assunzioni!$B$33,1) -> 1 | F23: =IF(F17>=Assunzioni!$B$32,Assunzioni!$B$33,1) -> 1 | G23: =IF(G17>=Assunzioni!$B$32,Assunzioni!$B$33,1) -> 1 | H23: =IF(H17>=Assunzioni!$B$32,Assunzioni!$B$33,1) -> 1 | I23: =IF(I17>=Assunzioni!$B$32,Assunzioni!$B$33,1) -> 1 | J23: =IF(J17>=Assunzioni!$B$32,Assunzioni!$B$33,1) -> 1 | ... Z23: =IF(Z17>=Assunzioni!$B$32,Assunzioni!$B$33,1) -> 2
A24: Nuovi utenti con match confermato nel mese | C24: =C19*C22*(1+(C23-1)*(1-Assunzioni!$B$34)) -> 0 | D24: =D19*D22*(1+(D23-1)*(1-Assunzioni!$B$34)) -> 0 | E24: =E19*E22*(1+(E23-1)*(1-Assunzioni!$B$34)) -> 0 | F24: =F19*F22*(1+(F23-1)*(1-Assunzioni!$B$34)) -> 14.333333 | G24: =G19*G22*(1+(G23-1)*(1-Assunzioni!$B$34)) -> 20.184667 | H24: =H19*H22*(1+(H23-1)*(1-Assunzioni!$B$34)) -> 27.097386 | I24: =I19*I22*(1+(I23-1)*(1-Assunzioni!$B$34)) -> 35.155505 | J24: =J19*J22*(1+(J23-1)*(1-Assunzioni!$B$34)) -> 54.195952 | ... Z24: =Z19*Z22*(1+(Z23-1)*(1-Assunzioni!$B$34)) -> 1129.9044
A25: Ricavi da match confermati (€) | C25: =C24*Assunzioni!$B$6 -> 0 | D25: =D24*Assunzioni!$B$6 -> 0 | E25: =E24*Assunzioni!$B$6 -> 0 | F25: =F24*Assunzioni!$B$6 -> 286.66667 | G25: =G24*Assunzioni!$B$6 -> 403.69333 | H25: =H24*Assunzioni!$B$6 -> 541.94772 | I25: =I24*Assunzioni!$B$6 -> 703.11009 | J25: =J24*Assunzioni!$B$6 -> 1083.919 | ... Z25: =Z24*Assunzioni!$B$6 -> 22598.089
A27: COSTI IT
A28: Claude Code | C28: =Assunzioni!$B$37 -> 25 | D28: =Assunzioni!$B$37 -> 25 | E28: =Assunzioni!$B$37 -> 25 | F28: =Assunzioni!$B$37 -> 25 | G28: =Assunzioni!$B$37 -> 25 | H28: =Assunzioni!$B$37 -> 25 | I28: =Assunzioni!$B$37 -> 25 | J28: =Assunzioni!$B$37 -> 25 | ... Z28: =Assunzioni!$B$37 -> 25
A29: Hosting | C29: =IF(C$2>=Assunzioni!$B$40,Assunzioni!$B$39,Assunzioni!$B$38) -> 20 | D29: =IF(D$2>=Assunzioni!$B$40,Assunzioni!$B$39,Assunzioni!$B$38) -> 20 | E29: =IF(E$2>=Assunzioni!$B$40,Assunzioni!$B$39,Assunzioni!$B$38) -> 20 | F29: =IF(F$2>=Assunzioni!$B$40,Assunzioni!$B$39,Assunzioni!$B$38) -> 20 | G29: =IF(G$2>=Assunzioni!$B$40,Assunzioni!$B$39,Assunzioni!$B$38) -> 20 | H29: =IF(H$2>=Assunzioni!$B$40,Assunzioni!$B$39,Assunzioni!$B$38) -> 20 | I29: =IF(I$2>=Assunzioni!$B$40,Assunzioni!$B$39,Assunzioni!$B$38) -> 20 | J29: =IF(J$2>=Assunzioni!$B$40,Assunzioni!$B$39,Assunzioni!$B$38) -> 20 | ... Z29: =IF(Z$2>=Assunzioni!$B$40,Assunzioni!$B$39,Assunzioni!$B$38) -> 35
A30: Costi API LLM (variabile su utenti attivi) | C30: =C17*Assunzioni!$B$41 -> 0 | D30: =D17*Assunzioni!$B$41 -> 0 | E30: =E17*Assunzioni!$B$41 -> 0 | F30: =F17*Assunzioni!$B$41 -> 8.6 | G30: =G17*Assunzioni!$B$41 -> 10.858 | H30: =H17*Assunzioni!$B$41 -> 13.221324 | I30: =I17*Assunzioni!$B$41 -> 15.709077 | J30: =J17*Assunzioni!$B$41 -> 22.150877 | ... Z30: =Z17*Assunzioni!$B$41 -> 257.53706
A31: Mailing tool | C31: =IF(C14>=Assunzioni!$B$45,Assunzioni!$B$46,0) -> 0 | D31: =IF(D14>=Assunzioni!$B$45,Assunzioni!$B$46,0) -> 0 | E31: =IF(E14>=Assunzioni!$B$45,Assunzioni!$B$46,0) -> 0 | F31: =IF(F14>=Assunzioni!$B$45,Assunzioni!$B$46,0) -> 0 | G31: =IF(G14>=Assunzioni!$B$45,Assunzioni!$B$46,0) -> 0 | H31: =IF(H14>=Assunzioni!$B$45,Assunzioni!$B$46,0) -> 0 | I31: =IF(I14>=Assunzioni!$B$45,Assunzioni!$B$46,0) -> 0 | J31: =IF(J14>=Assunzioni!$B$45,Assunzioni!$B$46,0) -> 0 | ... Z31: =IF(Z14>=Assunzioni!$B$45,Assunzioni!$B$46,0) -> 20
A32: Dominio (una tantum) | C32: =IF(C$2=0,Assunzioni!$B$42,0) -> 15 | D32: =IF(D$2=0,Assunzioni!$B$42,0) -> 0 | E32: =IF(E$2=0,Assunzioni!$B$42,0) -> 0 | F32: =IF(F$2=0,Assunzioni!$B$42,0) -> 0 | G32: =IF(G$2=0,Assunzioni!$B$42,0) -> 0 | H32: =IF(H$2=0,Assunzioni!$B$42,0) -> 0 | I32: =IF(I$2=0,Assunzioni!$B$42,0) -> 0 | J32: =IF(J$2=0,Assunzioni!$B$42,0) -> 0 | ... Z32: =IF(Z$2=0,Assunzioni!$B$42,0) -> 0
A33: Store fee App Mobile (una tantum) | C33: =IF(C$2=Assunzioni!$B$40,Assunzioni!$B$43+Assunzioni!$B$44,0) -> 0 | D33: =IF(D$2=Assunzioni!$B$40,Assunzioni!$B$43+Assunzioni!$B$44,0) -> 0 | E33: =IF(E$2=Assunzioni!$B$40,Assunzioni!$B$43+Assunzioni!$B$44,0) -> 0 | F33: =IF(F$2=Assunzioni!$B$40,Assunzioni!$B$43+Assunzioni!$B$44,0) -> 0 | G33: =IF(G$2=Assunzioni!$B$40,Assunzioni!$B$43+Assunzioni!$B$44,0) -> 0 | H33: =IF(H$2=Assunzioni!$B$40,Assunzioni!$B$43+Assunzioni!$B$44,0) -> 0 | I33: =IF(I$2=Assunzioni!$B$40,Assunzioni!$B$43+Assunzioni!$B$44,0) -> 0 | J33: =IF(J$2=Assunzioni!$B$40,Assunzioni!$B$43+Assunzioni!$B$44,0) -> 0 | ... Z33: =IF(Z$2=Assunzioni!$B$40,Assunzioni!$B$43+Assunzioni!$B$44,0) -> 0
A34: Totale Costi IT | C34: =SUM(C28:C33) -> 60 | D34: =SUM(D28:D33) -> 45 | E34: =SUM(E28:E33) -> 45 | F34: =SUM(F28:F33) -> 53.6 | G34: =SUM(G28:G33) -> 55.858 | H34: =SUM(H28:H33) -> 58.221324 | I34: =SUM(I28:I33) -> 60.709077 | J34: =SUM(J28:J33) -> 67.150877 | ... Z34: =SUM(Z28:Z33) -> 337.53706
A36: COSTI SOCIETARI / COMMERCIALISTA
A37: Commercialista (forfettario) / gestione SRL | C37: =IF(C$2<Assunzioni!$B$58,Assunzioni!$B$57,Assunzioni!$B$60/12) -> 50 | D37: =IF(D$2<Assunzioni!$B$58,Assunzioni!$B$57,Assunzioni!$B$60/12) -> 50 | E37: =IF(E$2<Assunzioni!$B$58,Assunzioni!$B$57,Assunzioni!$B$60/12) -> 50 | F37: =IF(F$2<Assunzioni!$B$58,Assunzioni!$B$57,Assunzioni!$B$60/12) -> 50 | G37: =IF(G$2<Assunzioni!$B$58,Assunzioni!$B$57,Assunzioni!$B$60/12) -> 50 | H37: =IF(H$2<Assunzioni!$B$58,Assunzioni!$B$57,Assunzioni!$B$60/12) -> 50 | I37: =IF(I$2<Assunzioni!$B$58,Assunzioni!$B$57,Assunzioni!$B$60/12) -> 50 | J37: =IF(J$2<Assunzioni!$B$58,Assunzioni!$B$57,Assunzioni!$B$60/12) -> 50 | ... Z37: =IF(Z$2<Assunzioni!$B$58,Assunzioni!$B$57,Assunzioni!$B$60/12) -> 833.33333
A38: Costituzione SRL (una tantum, al mese del passaggio) | C38: =IF(C$2=Assunzioni!$B$58,Assunzioni!$B$59,0) -> 0 | D38: =IF(D$2=Assunzioni!$B$58,Assunzioni!$B$59,0) -> 0 | E38: =IF(E$2=Assunzioni!$B$58,Assunzioni!$B$59,0) -> 0 | F38: =IF(F$2=Assunzioni!$B$58,Assunzioni!$B$59,0) -> 0 | G38: =IF(G$2=Assunzioni!$B$58,Assunzioni!$B$59,0) -> 0 | H38: =IF(H$2=Assunzioni!$B$58,Assunzioni!$B$59,0) -> 0 | I38: =IF(I$2=Assunzioni!$B$58,Assunzioni!$B$59,0) -> 0 | J38: =IF(J$2=Assunzioni!$B$58,Assunzioni!$B$59,0) -> 0 | ... Z38: =IF(Z$2=Assunzioni!$B$58,Assunzioni!$B$59,0) -> 0
A39: Totale Costi Societari | C39: =C37+C38 -> 50 | D39: =D37+D38 -> 50 | E39: =E37+E38 -> 50 | F39: =F37+F38 -> 50 | G39: =G37+G38 -> 50 | H39: =H37+H38 -> 50 | I39: =I37+I38 -> 50 | J39: =J37+J38 -> 50 | ... Z39: =Z37+Z38 -> 833.33333
A41: COSTI MARKETING & EVENTI
A42: Materiali promozionali — lotto iniziale (una tantum) | C42: =IF(C$2=0,Assunzioni!$B$49,0) -> 150 | D42: =IF(D$2=0,Assunzioni!$B$49,0) -> 0 | E42: =IF(E$2=0,Assunzioni!$B$49,0) -> 0 | F42: =IF(F$2=0,Assunzioni!$B$49,0) -> 0 | G42: =IF(G$2=0,Assunzioni!$B$49,0) -> 0 | H42: =IF(H$2=0,Assunzioni!$B$49,0) -> 0 | I42: =IF(I$2=0,Assunzioni!$B$49,0) -> 0 | J42: =IF(J$2=0,Assunzioni!$B$49,0) -> 0 | ... Z42: =IF(Z$2=0,Assunzioni!$B$49,0) -> 0
A43: Materiali promozionali — ristampe (ricorrente da M1) | C43: =IF(C$2>=1,Assunzioni!$B$50,0) -> 0 | D43: =IF(D$2>=1,Assunzioni!$B$50,0) -> 40 | E43: =IF(E$2>=1,Assunzioni!$B$50,0) -> 40 | F43: =IF(F$2>=1,Assunzioni!$B$50,0) -> 40 | G43: =IF(G$2>=1,Assunzioni!$B$50,0) -> 40 | H43: =IF(H$2>=1,Assunzioni!$B$50,0) -> 40 | I43: =IF(I$2>=1,Assunzioni!$B$50,0) -> 40 | J43: =IF(J$2>=1,Assunzioni!$B$50,0) -> 40 | ... Z43: =IF(Z$2>=1,Assunzioni!$B$50,0) -> 40
A44: Servizio distribuzione mirata Milano (ricorrente) | C44: =IF(C$2>=Assunzioni!$B$16,Assunzioni!$B$14,0) -> 0 | D44: =IF(D$2>=Assunzioni!$B$16,Assunzioni!$B$14,0) -> 100 | E44: =IF(E$2>=Assunzioni!$B$16,Assunzioni!$B$14,0) -> 100 | F44: =IF(F$2>=Assunzioni!$B$16,Assunzioni!$B$14,0) -> 100 | G44: =IF(G$2>=Assunzioni!$B$16,Assunzioni!$B$14,0) -> 100 | H44: =IF(H$2>=Assunzioni!$B$16,Assunzioni!$B$14,0) -> 100 | I44: =IF(I$2>=Assunzioni!$B$16,Assunzioni!$B$14,0) -> 100 | J44: =IF(J$2>=Assunzioni!$B$16,Assunzioni!$B$14,0) -> 100 | ... Z44: =IF(Z$2>=Assunzioni!$B$16,Assunzioni!$B$14,0) -> 100
A45: Budget Ads totale (calcolato, capped da cassa) | C45: =MAX(0,MIN(Assunzioni!$B$51+Assunzioni!$B$52*0,C58-Assunzioni!$B$7)) -> 200 | D45: =MAX(0,MIN(Assunzioni!$B$51+Assunzioni!$B$52*C25,D58-Assunzioni!$B$7)) -> 200 | E45: =MAX(0,MIN(Assunzioni!$B$51+Assunzioni!$B$52*D25,E58-Assunzioni!$B$7)) -> 200 | F45: =MAX(0,MIN(Assunzioni!$B$51+Assunzioni!$B$52*E25,F58-Assunzioni!$B$7)) -> 200 | G45: =MAX(0,MIN(Assunzioni!$B$51+Assunzioni!$B$52*F25,G58-Assunzioni!$B$7)) -> 286 | H45: =MAX(0,MIN(Assunzioni!$B$51+Assunzioni!$B$52*G25,H58-Assunzioni!$B$7)) -> 321.108 | I45: =MAX(0,MIN(Assunzioni!$B$51+Assunzioni!$B$52*H25,I58-Assunzioni!$B$7)) -> 362.58432 | J45: =MAX(0,MIN(Assunzioni!$B$51+Assunzioni!$B$52*I25,J58-Assunzioni!$B$7)) -> 410.93303 | K45: =MAX(0,MIN(Assunzioni!$B$51+Assunzioni!$B$52*J25,K58-Assunzioni!$B$7)) -> 525.17571 | ... Z45: =MAX(0,MIN(Assunzioni!$B$51+Assunzioni!$B$52*Y25,Z58-Assunzioni!$B$7)) -> 6199.0351
...

Sheet Sintesi
A1: AInima — Sintesi & Break-Even
A3: PUNTO DI PAREGGIO (BREAK-EVEN)
A4: Primo mese con utile mensile positivo | B4: =IFERROR("M"&(MATCH(1,'Piano Mensile'!C60:Z60,0)-1),"Non raggiunto entro 24 mesi") -> M7
A5: Ricavi in quel mese | B5: =IFERROR(INDEX('Piano Mensile'!C55:Z55,MATCH(1,'Piano Mensile'!C60:Z60,0)),0) -> 1083.919
A6: Iscritti totali in quel mese | B6: =IFERROR(INDEX('Piano Mensile'!C14:Z14,MATCH(1,'Piano Mensile'!C60:Z60,0)),0) -> 553.77191
A8: CASSA
A9: Cassa minima toccata nei 24 mesi (punto più critico) | B9: =MIN('Piano Mensile'!C59:Z59) -> 2769.9204
A10: Mese in cui si tocca il minimo | B10: ="M"&INDEX('Piano Mensile'!C2:Z2,MATCH(MIN('Piano Mensile'!C59:Z59),'Piano Mensile'!C59:Z59,0)) -> M6
A11: Cassa disponibile a fine M11 (1 anno) | B11: ='Piano Mensile'!N59 -> 10808.825
A12: Cassa disponibile a fine M23 (2 anni) | B12: ='Piano Mensile'!Z59 -> 99075.146
A14: REDDITIVITÀ
A15: Ricavi cumulati primi 12 mesi (M0-M11) | B15: =SUM('Piano Mensile'!C55:N55) -> 16266.527
A16: Ricavi cumulati 24 mesi | B16: =SUM('Piano Mensile'!C55:Z55) -> 163566.97
A17: Utile/Perdita cumulato primi 12 mesi | B17: =SUM('Piano Mensile'!C57:N57) -> 5808.8252
A18: Utile/Perdita cumulato 24 mesi | B18: =SUM('Piano Mensile'!C57:Z57) -> 94075.146
A19: Utile mensile a regime (M23) | B19: ='Piano Mensile'!Z57 -> 14184.26
A20: Margine % sui ricavi a M23 | B20: =IFERROR('Piano Mensile'!Z57/'Piano Mensile'!Z55,0) -> 0.62767519
A22: UTENTI E DATABASE
A23: Iscritti totali a fine M11 (1 anno) | B23: ='Piano Mensile'!N14 -> 1171.1508
A24: Iscritti totali a fine M23 (2 anni) | B24: ='Piano Mensile'!Z14 -> 6438.4265
A25: Utenti attivi a M23 | B25: ='Piano Mensile'!Z17 -> 5150.7412
A27: INVESTIMENTO TOTALE PER CATEGORIA (24 mesi)
A28: Costi IT totali | B28: =SUM('Piano Mensile'!C34:Z34) -> 3488.4828
A29: Costi Marketing & Eventi totali | B29: =SUM('Piano Mensile'!C49:Z49) -> 51060.665
A30: Commissioni di pagamento totali | B30: =SUM('Piano Mensile'!C52:Z52) -> 6542.6789
A32: Nota: tutti i valori sono calcolati dalle formule del foglio 'Piano Mensile', che a sua volta dipende interamente dalle ipotesi nel foglio 'Assunzioni'. Cambia i numeri blu in 'Assunzioni' per testare scenari diversi (es. CAC più alto, tasso di conferma più basso, budget iniziale diverso).

Sheet Note e Fonti
A1: Note metodologiche e fonti
A3: COME LEGGERE IL MODELLO
A4: Il modello è composto da 4 fogli: Assunzioni (input, celle blu/gialle), Piano Mensile (calcolo mese per mese da M0 a M23),
A5: Sintesi (KPI e break-even) e questo foglio di note. Cambiando un valore in 'Assunzioni' tutto il piano si ricalcola.
A7: PRINCIPALI SEMPLIFICAZIONI DEL MODELLO
A8: • Il prezzo di 10€ per 'match confermato' è addebitato a ciascuno dei due utenti coinvolti (10€ x 2 = 20€ per coppia formata).
A9: • FUNNEL: ogni mese le proposte si applicano solo agli utenti 'in ricerca attiva' (attivi totali meno chi ha abbandonato
A10: la ricerca). Un match confermato NON fa uscire l'utente dal pool — resta disponibile per altre proposte in futuro,
A11: come una rubrica di contatti che si arricchisce nel tempo. Solo un tasso di ABBANDONO generale (chi lascia per
A12: qualsiasi motivo: relazione stabile trovata altrove, rinuncia) riduce il pool, indipendentemente dai match confermati.
A13: • FREQUENZA DI ABBINAMENTO ELASTICA: il vincolo di '1 proposta al mese' non è un limite tecnico ma una scelta di prodotto
A14: per far crescere il database senza esaurirlo. Il vero limite alla frequenza non è 'finire le persone' ma il ranking:
... A60: reinvestito nell'avvio; è una scelta cosciente ma da tenere presente come costo-opportunità.

Sheet Costituzione Società
A1: AInima — Apertura società: Milano vs Dubai
A2: Stime basate su fonti pubbliche aggiornate al 2026 (vedi Note e Fonti). Non sostituiscono la consulenza di un commercialista/tax advisor locale — verificare sempre prima di procedere.
A4: MILANO — ITALIA | D4: DUBAI — EMIRATI ARABI UNITI
A5: Opzione A: Partita IVA — Regime Forfettario | D5: Free Zone company (es. IFZA/Meydan, 0-1 visto)
A6: Costo apertura (0€ fai-da-te, fino a ~600€ con commercialista) | B6: 400 | D6: Setup iniziale free zone (licenza + registrazione, 0 visti) | E6: 5500
A7: Contributi INPS Gestione Separata (% su imponibile) | B7: 0.2607 | D7: Rinnovo licenza + accounting/audit (€/anno, dal 2° anno) | E7: 3200
A8: Coefficiente di redditività forfettario (verificare ATECO specifico) | B8: 0.78
A9: Imposta sostitutiva primi 5 anni / dal 6° anno | B9: 5% / 15%
A11: Opzione B: SRL (eventualmente SRL innovativa) | D11: Mainland LLC (se servono clienti/contratti locali diretti)
A12: Notaio + commercialista costituzione (una tantum) | B12: 2500 | D12: Setup iniziale mainland (licenza + 1 visto + ufficio) | E12: 35000
A13: Costi fissi annui gestione (CCIAA, PEC, commercialista, INPS min.) | B13: 10000 | D13: Rinnovo + accounting/audit + visto (€/anno) | E13: 15000
A14: IRES + IRAP sull'utile | B14: 0.279 | D14: Corporate tax UAE su utile sopra soglia AED 375.000 (~92.500€) | E14: 0.09
A15: Ritenuta su dividendi distribuiti ai soci | B15: 0.26 | D15: Corporate tax sotto soglia AED 375.000 | E15: 0
A17: ESEMPIO NUMERICO — sui risultati reali del Piano Mensile
A18: Ricavi anno 1 (M0-M11) | B18: ='Piano Mensile'!C55+'Piano Mensile'!D55+'Piano Mensile'!E55+'Piano Mensile'!F55+'Piano Mensile'!G55+'Piano Mensile'!H55+'Piano Mensile'!I55+'Piano Mensile'!J55+'Piano Mensile'!K55+'Piano Mensile'!L55+'Piano Mensile'!M55+'Piano Mensile'!N55 -> 16266.527 | D18: Ricavi anno 2 (M12-M23) | E18: ='Piano Mensile'!O55+'Piano Mensile'!P55+'Piano Mensile'!Q55+'Piano Mensile'!R55+'Piano Mensile'!S55+'Piano Mensile'!T55+'Piano Mensile'!U55+'Piano Mensile'!V55+'Piano Mensile'!W55+'Piano Mensile'!X55+'Piano Mensile'!Y55+'Piano Mensile'!Z55 -> 147300.45
A19: Utile ante imposte anno 1 (reale, costi dedotti) | B19: ='Piano Mensile'!C57+'Piano Mensile'!D57+'Piano Mensile'!E57+'Piano Mensile'!F57+'Piano Mensile'!G57+'Piano Mensile'!H57+'Piano Mensile'!I57+'Piano Mensile'!J57+'Piano Mensile'!K57+'Piano Mensile'!L57+'Piano Mensile'!M57+'Piano Mensile'!N57 -> 5808.8252 | D19: Utile ante imposte anno 2 (reale, costi dedotti) | E19: ='Piano Mensile'!O57+'Piano Mensile'!P57+'Piano Mensile'!Q57+'Piano Mensile'!R57+'Piano Mensile'!S57+'Piano Mensile'!T57+'Piano Mensile'!U57+'Piano Mensile'!V57+'Piano Mensile'!W57+'Piano Mensile'!X57+'Piano Mensile'!Y57+'Piano Mensile'!Z57 -> 88266.321
A21: Forfettario — base imponibile REALE (fatturato x coefficiente, non l'utile) | D21: Dubai — imposta stimata anno 1 e 2 (in €, cambio indicativo 1€≈4,0 AED)
A22: Imponibile forfettario anno 1 (ricavi x coefficiente) | B22: =B18*B8 -> 12687.891 | D22: Soglia esente (AED 375.000 ≈) | E22: 92500
A23: Imposta sostitutiva anno 1 (5%) | B23: =B22*0.05 -> 634.39456 | D23: Imposta anno 1 (utile molto sotto soglia) | E23: =IF(B19>E22,(B19-E22)*E8,0) -> 0
A24: Contributi INPS anno 1 (26,07% su imponibile) | B24: =B22*B7 -> 3307.7332 | D24: Imposta anno 2 (utile ancora sotto soglia in questo scenario) | E24: =IF(E19>E22,(E19-E22)*E8,0) -> 0
A25: Netto reale anno 1 (utile reale - imposta - INPS) | B25: =B19-B23-B24 -> 1866.6974 | D25: Netto reale anno 1 e 2 Dubai (nessuna imposta in questo scenario) | E25: =B19+E19-E23-E24 -> 94075.146 | F25: ← valido solo sotto soglia 92.500€/anno; verificare con advisor UAE
A26: ⚠ Nota: se il coefficiente presunto (78%) supera il margine reale del business, si pagano tasse su un profitto presunto MAGGIORE di quello reale — capita spesso nei primi mesi, quando i costi di acquisizione sono alti rispetto ai ricavi.
A29: SINTESI — cosa cambia davvero
A30: • Milano, anno 1: il forfettario funziona bene sui costi di apertura (quasi gratis), ma la base imponibile presunta (78% del fatturato) può superare l'utile reale nei mesi di ramp-up — verificare il coefficiente ATECO corretto con un commercialista prima di scegliere.
A31: • Milano, anno 2: il fatturato (~82.000€) si avvicina alla soglia degli 85.000€ del forfettario — con la crescita prevista, il passaggio a SRL (o SRL innovativa, che ha comunque le stesse aliquote IRES/IRAP ma agevolazioni su costituzione e investitori) diventa necessario entro l'anno 2.
A32: • Dubai: sia con QFZP pieno sia (più probabilmente, dato che i clienti finali sono probabilmente residenti a Dubai/mainland, quindi reddito non 'qualifying') con il regime standard da persona tassabile ordinaria, si applica comunque la soglia UNIVERSALE 0% fino a 375.000 AED (~92.500€) di utile, 9% sopra — questa soglia di base non dipende dallo status free zone e non ha scadenza. Ai livelli di utile di questo piano (sotto soglia in entrambi gli anni), la tassazione stimata è 0€. Non è però una condizione permanente: se l'utile di Dubai superasse ~92.500€/anno in futuro, il 9% scatterebbe sulla parte eccedente, a prescindere dallo status free zone, proprio perché il reddito da clienti locali difficilmente si qualifica per l'esenzione aggiuntiva senza soglia riservata alle free zone.
A33: • Small Business Relief (0% fino a 3 milioni di AED di fatturato, non di utile) è un'agevolazione ULTERIORE e separata dalla soglia universale sopra — disponibile solo per periodi d'imposta che terminano entro il 31/12/2026, salvo proroghe non confermate. Anche senza questa agevolazione, la soglia universale sui primi 375.000 AED di utile resta comunque valida. Verificare con un tax advisor UAE la classificazione esatta del reddito prima di aprire la società — il quadro normativo è recente (dal 2023) e in evoluzione.
A34: • I costi di gestione superano il beneficio fiscale: a Dubai i costi fissi ricorrenti (licenza, audit, eventuale visto) partono da ~3.000-4.000€/anno anche a tassazione zero — vanno confrontati con il fatturato atteso in quel mercato, non solo con l'aliquota.
